{
 "cells": [
  {
   "cell_type": "markdown",
   "metadata": {},
   "source": [
    "## Import Standard Libraries"
   ]
  },
  {
   "cell_type": "code",
   "execution_count": 4,
   "metadata": {},
   "outputs": [],
   "source": [
    "import numpy as np\n",
    "import pandas as pd\n",
    "\n",
    "%matplotlib inline\n",
    "import matplotlib.pyplot as plt\n",
    "import seaborn as sns\n",
    "import sklearn"
   ]
  },
  {
   "cell_type": "code",
   "execution_count": 9,
   "metadata": {},
   "outputs": [
    {
     "name": "stderr",
     "output_type": "stream",
     "text": [
      "ERROR:root:Internal Python error in the inspect module.\n",
      "Below is the traceback from this internal error.\n",
      "\n"
     ]
    },
    {
     "name": "stdout",
     "output_type": "stream",
     "text": [
      "Traceback (most recent call last):\n",
      "  File \"/Library/Frameworks/Python.framework/Versions/3.8/lib/python3.8/site-packages/IPython/core/interactiveshell.py\", line 3331, in run_code\n",
      "    exec(code_obj, self.user_global_ns, self.user_ns)\n",
      "  File \"<ipython-input-9-b0c435917697>\", line 1, in <module>\n",
      "    data = pd.read_csv(\"tree/Dataset/all_sources_metadata_2020-03-13.csv\")\n",
      "  File \"/Library/Frameworks/Python.framework/Versions/3.8/lib/python3.8/site-packages/pandas/io/parsers.py\", line 676, in parser_f\n",
      "    return _read(filepath_or_buffer, kwds)\n",
      "  File \"/Library/Frameworks/Python.framework/Versions/3.8/lib/python3.8/site-packages/pandas/io/parsers.py\", line 448, in _read\n",
      "    parser = TextFileReader(fp_or_buf, **kwds)\n",
      "  File \"/Library/Frameworks/Python.framework/Versions/3.8/lib/python3.8/site-packages/pandas/io/parsers.py\", line 880, in __init__\n",
      "    self._make_engine(self.engine)\n",
      "  File \"/Library/Frameworks/Python.framework/Versions/3.8/lib/python3.8/site-packages/pandas/io/parsers.py\", line 1114, in _make_engine\n",
      "    self._engine = CParserWrapper(self.f, **self.options)\n",
      "  File \"/Library/Frameworks/Python.framework/Versions/3.8/lib/python3.8/site-packages/pandas/io/parsers.py\", line 1891, in __init__\n",
      "    self._reader = parsers.TextReader(src, **kwds)\n",
      "  File \"pandas/_libs/parsers.pyx\", line 374, in pandas._libs.parsers.TextReader.__cinit__\n",
      "  File \"pandas/_libs/parsers.pyx\", line 674, in pandas._libs.parsers.TextReader._setup_parser_source\n",
      "FileNotFoundError: [Errno 2] File tree/Dataset/all_sources_metadata_2020-03-13.csv does not exist: 'tree/Dataset/all_sources_metadata_2020-03-13.csv'\n",
      "\n",
      "During handling of the above exception, another exception occurred:\n",
      "\n",
      "Traceback (most recent call last):\n",
      "  File \"/Library/Frameworks/Python.framework/Versions/3.8/lib/python3.8/site-packages/IPython/core/interactiveshell.py\", line 2044, in showtraceback\n",
      "    stb = value._render_traceback_()\n",
      "AttributeError: 'FileNotFoundError' object has no attribute '_render_traceback_'\n",
      "\n",
      "During handling of the above exception, another exception occurred:\n",
      "\n",
      "Traceback (most recent call last):\n",
      "  File \"/Library/Frameworks/Python.framework/Versions/3.8/lib/python3.8/site-packages/IPython/core/ultratb.py\", line 1148, in get_records\n",
      "    return _fixed_getinnerframes(etb, number_of_lines_of_context, tb_offset)\n",
      "  File \"/Library/Frameworks/Python.framework/Versions/3.8/lib/python3.8/site-packages/IPython/core/ultratb.py\", line 316, in wrapped\n",
      "    return f(*args, **kwargs)\n",
      "  File \"/Library/Frameworks/Python.framework/Versions/3.8/lib/python3.8/site-packages/IPython/core/ultratb.py\", line 350, in _fixed_getinnerframes\n",
      "    records = fix_frame_records_filenames(inspect.getinnerframes(etb, context))\n",
      "  File \"/Library/Frameworks/Python.framework/Versions/3.8/lib/python3.8/inspect.py\", line 1503, in getinnerframes\n",
      "    frameinfo = (tb.tb_frame,) + getframeinfo(tb, context)\n",
      "  File \"/Library/Frameworks/Python.framework/Versions/3.8/lib/python3.8/inspect.py\", line 1461, in getframeinfo\n",
      "    filename = getsourcefile(frame) or getfile(frame)\n",
      "  File \"/Library/Frameworks/Python.framework/Versions/3.8/lib/python3.8/inspect.py\", line 708, in getsourcefile\n",
      "    if getattr(getmodule(object, filename), '__loader__', None) is not None:\n",
      "  File \"/Library/Frameworks/Python.framework/Versions/3.8/lib/python3.8/inspect.py\", line 737, in getmodule\n",
      "    file = getabsfile(object, _filename)\n",
      "  File \"/Library/Frameworks/Python.framework/Versions/3.8/lib/python3.8/inspect.py\", line 721, in getabsfile\n",
      "    return os.path.normcase(os.path.abspath(_filename))\n",
      "  File \"/Library/Frameworks/Python.framework/Versions/3.8/lib/python3.8/posixpath.py\", line 379, in abspath\n",
      "    cwd = os.getcwd()\n",
      "PermissionError: [Errno 1] Operation not permitted\n"
     ]
    },
    {
     "ename": "FileNotFoundError",
     "evalue": "[Errno 2] File tree/Dataset/all_sources_metadata_2020-03-13.csv does not exist: 'tree/Dataset/all_sources_metadata_2020-03-13.csv'",
     "output_type": "error",
     "traceback": [
      "\u001b[0;31m---------------------------------------------------------------------------\u001b[0m"
     ]
    }
   ],
   "source": [
    "data = pd.read_csv(\"tree/Dataset/all_sources_metadata_2020-03-13.csv\")"
   ]
  },
  {
   "cell_type": "code",
   "execution_count": null,
   "metadata": {},
   "outputs": [],
   "source": []
  }
 ],
 "metadata": {
  "kernelspec": {
   "display_name": "Python 3",
   "language": "python",
   "name": "python3"
  },
  "language_info": {
   "codemirror_mode": {
    "name": "ipython",
    "version": 3
   },
   "file_extension": ".py",
   "mimetype": "text/x-python",
   "name": "python",
   "nbconvert_exporter": "python",
   "pygments_lexer": "ipython3",
   "version": "3.8.2"
  }
 },
 "nbformat": 4,
 "nbformat_minor": 4
}
